<?xml version="1.0" ?>
<!-- =================================================================================== -->
<!-- |    This document was autogenerated by xacro from single_rrbot.urdf.xacro        | -->
<!-- |    EDITING THIS FILE BY HAND IS NOT RECOMMENDED                                 | -->
<!-- =================================================================================== -->
<robot name="door" xmlns:xacro="http://www.ros.org/wiki/xacro">
  <!-- Import your models -->
  <material name="RRBOT/black">
    <color rgba="0.0 0.0 0.0 1.0"/>
  </material>
  <material name="RRBOT/blue">
    <color rgba="0.0 0.0 0.8 1.0"/>
  </material>
  <material name="RRBOT/green">
    <color rgba="0.0 0.8 0.0 1.0"/>
  </material>
  <material name="RRBOT/grey">
    <color rgba="0.2 0.2 0.2 1.0"/>
  </material>
  <material name="RRBOT/orange">
    <color rgba="1.0 0.423529411765 0.0392156862745 1.0"/>
  </material>
  <material name="RRBOT/brown">
    <color rgba="0.870588235294 0.811764705882 0.764705882353 1.0"/>
  </material>
  <material name="RRBOT/red">
    <color rgba="0.8 0.0 0.0 1.0"/>
  </material>
  <material name="RRBOT/white">
    <color rgba="1.0 1.0 1.0 1.0"/>
  </material>
  <!-- Build your comprehensive robot -->
  <link name="world"/>
  <gazebo reference="world">
    <static>true</static>
  </gazebo>
  <joint name="door_world" type="continuous">
    <origin rpy="0 0 0" xyz="0 0 0"/>
    <axis xyz="0 0 1"/>
    <parent link="world"/>
    <child link="door"/>
  </joint>
  <link name="door">
    <collision>
      <origin rpy="0 0 0" xyz="0 0.5 1"/>
      <geometry>
        <box size="0.1 1 2"/>
      </geometry>
    </collision>
    <visual>
      <origin rpy="0 0 0" xyz="0 0.5 1"/>
      <geometry>
        <box size="0.1 1 2"/>
      </geometry>
      <material name="RRBOT/orange"/>
    </visual>
    <inertial>
      <origin rpy="0 0 0" xyz="0 0 1.0"/>
      <mass value="1"/>
      <inertia ixx="1.0" ixy="0.0" ixz="0.0" iyy="1.0" iyz="0.0" izz="1.0"/>
    </inertial>
  </link>
  <joint name="frame1_world" type="fixed">
    <origin rpy="0 0 0" xyz="0 0 0"/>
    <axis xyz="0 0 1"/>
    <parent link="world"/>
    <child link="frame1"/>
  </joint>
  <link name="frame1">
    <collision>
      <origin rpy="0 0 0" xyz="0 -0.05 1.05"/>
      <geometry>
        <box size="0.1 0.1 2.1"/>
      </geometry>
    </collision>
    <visual>
      <origin rpy="0 0 0" xyz="0 -0.05 1.05"/>
      <geometry>
        <box size="0.1 0.1 2.1"/>
      </geometry>
      <material name="RRBOT/orange"/>
    </visual>
    <inertial>
      <origin rpy="0 0 0" xyz="0 0 1.0"/>
      <mass value="1"/>
      <inertia ixx="1.0" ixy="0.0" ixz="0.0" iyy="1.0" iyz="0.0" izz="1.0"/>
    </inertial>
  </link>
  <joint name="frame2_world" type="fixed">
    <origin rpy="0 0 0" xyz="0 0 0"/>
    <axis xyz="0 0 1"/>
    <parent link="world"/>
    <child link="frame2"/>
  </joint>
  <link name="frame2">
    <collision>
      <origin rpy="0 0 0" xyz="0 1.05 1.05"/>
      <geometry>
        <box size="0.1 0.1 2.1"/>
      </geometry>
    </collision>
    <visual>
      <origin rpy="0 0 0" xyz="0 1.05 1.05"/>
      <geometry>
        <box size="0.1 0.1 2.1"/>
      </geometry>
      <material name="RRBOT/orange"/>
    </visual>
    <inertial>
      <origin rpy="0 0 0" xyz="0 0 1.0"/>
      <mass value="1"/>
      <inertia ixx="1.0" ixy="0.0" ixz="0.0" iyy="1.0" iyz="0.0" izz="1.0"/>
    </inertial>
  </link>
   <joint name="frame3_world" type="fixed">
    <origin rpy="0 0 0" xyz="0 0 0"/>
    <axis xyz="0 0 1"/>
    <parent link="world"/>
    <child link="frame3"/>
  </joint>
  <link name="frame3">
    <collision>
      <origin rpy="0 0 0" xyz="0 0.5 2.05"/>
      <geometry>
        <box size="0.1 1.1 0.1"/>
      </geometry>
    </collision>
    <visual>
      <origin rpy="0 0 0" xyz="0 0.5 2.05"/>
      <geometry>
        <box size="0.1 1.1 0.1"/>
      </geometry>
      <material name="RRBOT/orange"/>
    </visual>
    <inertial>
      <origin rpy="0 0 0" xyz="0 0 1.0"/>
      <mass value="1"/>
      <inertia ixx="1.0" ixy="0.0" ixz="0.0" iyy="1.0" iyz="0.0" izz="1.0"/>
    </inertial>
  </link>
</robot>

<!--   
  <transmission name="single_rrbot_tran1">
    <type>transmission_interface/SimpleTransmission</type>
    <joint name="2single_rrbot_joint1">
      <hardwareInterface>PositionJointInterface</hardwareInterface>
    </joint>
    <actuator name="single_rrbot_motor1">
      <mechanicalReduction>1</mechanicalReduction>
    </actuator>
  </transmission>
  <transmission name="single_rrbot_tran2">
    <type>transmission_interface/SimpleTransmission</type>
    <joint name="2single_rrbot_joint2">
      <hardwareInterface>PositionJointInterface</hardwareInterface>
    </joint>
    <actuator name="single_rrbot_motor2">
      <mechanicalReduction>1</mechanicalReduction>
    </actuator>
  </transmission>
  <gazebo>
    <plugin filename="librrbot_hw_sim_plugin.so" name="single_rrbot_hw_sim_plugin">
      <robotNamespace>single_rrbot</robotNamespace>
      <!-- add your custom sim behavior -->
      <robotSimType>rrbot_hw/DefaultRRBOTHWSim</robotSimType>
    </plugin>
  </gazebo>
  <gazebo reference="2single_rrbot_link1">
    <material>Gazebo/Orange</material>
  </gazebo>
  <gazebo reference="2single_rrbot_link2">
    <mu1>0.2</mu1>
    <mu2>0.2</mu2>
    <material>Gazebo/Black</material>
  </gazebo>
  <gazebo reference="2single_rrbot_link3">
    <mu1>0.2</mu1>
    <mu2>0.2</mu2>
    <material>Gazebo/Orange</material>
  </gazebo> 
-->
