<?xml version="1.0" encoding="utf-8"?>
<!-- =================================================================================== -->
<!-- |    This document was autogenerated by xacro from meca_500_r3.urdf.xacro         | -->
<!-- |    EDITING THIS FILE BY HAND IS NOT RECOMMENDED                                 | -->
<!-- =================================================================================== -->
<robot name="cube_product" xmlns:xacro="http://ros.org/wiki/xacro">

  <link name="/cubes/c1/cube">
    <visual>
      <origin rpy="0 0 0" xyz="0 0 0"/>
      <geometry>
        <mesh filename="package://ros2_mecademic_description/meshes/meca_500_r3_base.dae"/>
      </geometry>
      <material name="Green">
        <color rgba="0 1 0 1.0"/>
      </material>
    </visual>
    <collision>
      <origin rpy="0 0 0" xyz="0 0 0"/>
      <geometry>
        <box size="0.05 0.05 0.05" />
      </geometry>
    </collision>
  </link>

  <link name="/cubes/c1/cube_fake">
    <visual>
      <origin rpy="0 0 0" xyz="0 0 0"/>
      <geometry>
        <mesh filename="package://ros2_mecademic_description/meshes/meca_500_r3_base.dae"/>
      </geometry>
      <material name="Green">
        <color rgba="0 1 0 1.0"/>
      </material>
    </visual>
    <collision>
      <origin rpy="0 0 0" xyz="0 0 0"/>
      <geometry>
        <box size="0.05 0.05 0.05" />
      </geometry>
    </collision>
  </link>

  <joint name="cube_to_cube_fake" type="revolute">
    <origin rpy="0 0 0.1" xyz="0 0 0.1"/>
    <parent link="/cubes/c1/cube"/>
    <child link="/cubes/c1/cube_fake"/>
    <axis xyz="1 0 0"/>
    <limit effort="10.0" lower="-3.14159" upper="3.14159" velocity="8.72665"/>
  </joint>
  
</robot>
